<mujoco model="intention">
  <compiler angle="radian" meshdir="meshes" autolimits="true"/>

  <option iterations="2" ls_iterations="5" gravity="0.0 0.0 -9.81">
    <flag eulerdamp="disable" />
  </option>

  <asset>
    <material name="metal" rgba=".9 .95 .95 1" />
    <material name="black" rgba="0 0 0 1" />
    <material name="white" rgba="1 1 1 1" />
    <material name="gray" rgba="0.6 0.6 0.6 1" />
    <material name="orange" rgba="1 0.41 0 1" />

    <mesh name="body" file="body.stl" scale="0.001 0.001 0.001"/>
    <mesh name="rear" file="rear.stl" scale="0.001 0.001 0.001"/>
    <mesh name="l0r" file="l0r.stl" scale="0.001 0.001 0.001"/>
    <mesh name="l1r" file="l1r.stl" scale="0.001 0.001 0.001"/>
    <mesh name="l2r" file="l2r.stl" scale="0.001 0.001 0.001"/>
    <mesh name="l0l" file="l0l.stl" scale="0.001 0.001 0.001"/>
    <mesh name="l1lf" file="l1lf.stl" scale="0.001 0.001 0.001"/>
    <mesh name="l2l" file="l2l.stl" scale="0.001 0.001 0.001"/>
  </asset>

  <default>
      <default class="sb">
          <geom condim="1" friction="0.6" margin="0.001" />
          <joint axis="1 0 0" stiffness="0.0" damping="0.65" armature="0.013122"/>
          <default class="spine">
            <motor ctrlrange="-48 48" ctrllimited="true"/>
          </default>
          <default class="hip">
            <!-- <joint range="-1.57 1.57"/> -->
            <!-- <joint range="-1.0 1.0"/> -->
            <joint range="-0.1 0.1"/>
            <motor ctrlrange="-16 16" ctrllimited="true" />
          </default>
          <default class="thigh">
            <joint range="-1.57 1.57"/>
            <motor ctrlrange="-16 16" ctrllimited="true"/>
          </default>
          <default class="calf">
            <motor ctrlrange="-16 16" ctrllimited="true"/>
            <default class="left_calf">
              <joint range="0 2.53"/>
            </default>
            <default class="right_calf">
              <joint range="-2.53 0"/>
            </default>
          </default>
          <default class="visual">
            <geom type="mesh" contype="0" conaffinity="0" group="2" />
            <default class="visual_foot">
              <geom type="sphere" size="0.021" material="black" />
              <default class="left_visual_foot">
                <geom pos="0.0054 0.2 0" />
              </default>
              <default class="right_visual_foot">
                <geom pos="0.0054 -0.2 0" />
              </default>
            </default>
          </default>
          <default class="foot">
            <geom type="sphere" size="0.02" solimp="0.015 1 0.031"
                  friction="0.6 0.02 0.01" condim="3" material="black" />
            <default class="left_foot">
              <geom pos="0.0054 0.2 0" />
              <site group="1" pos="0.0054 0.2 0" />
            </default>
            <default class="right_foot">
              <geom pos="0.0054 -0.2 0" />
              <site group="1" pos="0.0054 -0.2 0" />
            </default>
          </default>
      </default>
  </default>

  <worldbody>
    <light cutoff="100" diffuse="1 1 1" dir="-0 0 -1.3" directional="true" exponent="1" pos="0 0 1.3" specular=".1 .1 .1" castshadow="false"/>
    <light name="spotlight" mode="targetbodycom" target="trunk" pos="0 -1 2"/>

    <body name="trunk" childclass="sb">
      <!-- <camera name="track" mode="trackcom" pos="0 -2 0" xyaxes="1 0 0 0 0 1"/> -->
      <camera name="track" pos="0.846 -1.465 0.916" xyaxes="0.866 0.500 0.000 -0.171 0.296 0.940" mode="trackcom" />
      <freejoint/>

      <inertial mass="5.423" pos="0 0 0" diaginertia="0.02164656458935 0.0407033948939 0.05472198086004"/>

      <geom mesh="body" material="gray" class="visual"/>
      <!-- TODO: COLISSION BODIES -->
      <!-- <geom size="0.11 0.07 0.045" pos="0.025 0 0" type="box" rgba="0.6 0.6 0.6 1"/> -->
      <!-- <geom name="trunk_1" size="0.05 0.11" pos="0.025 0.064 0" quat="0.707388 0 0.706825 0" type="cylinder" rgba="0.6 0.6 0.6 1"/> -->
      <!-- <geom name="trunk_2" size="0.05 0.11" pos="0.025 -0.064 0" quat="0.707388 0 0.706825 0" type="cylinder" rgba="0.6 0.6 0.6 1"/> -->

      <body name="rear" pos="-0.141 -0.0395 0" quat="-9.37064e-07 -0.706262 0.707951 9.39306e-07">
        <inertial pos="-0.038 0.075 0" quat="0.5 0.5 -0.5 0.5" mass="1.337" diaginertia="0.00509714 0.00464543 0.00198234" />
        <joint name="spine_joint" range="-0.0000001 0." />
        <!-- <joint name="spine_joint" range="0 0" /> -->
        <!-- <joint name="spine_joint"  range="-0.785 0.785" /> -->
        <geom mesh="rear" material="gray" class="visual" />

        <!-- TODO: COLISSION BODIES -->
        <!-- <geom size="0.1 0.025 0.05" pos="-0.04 0.08 0" type="box" rgba="0.6 0.6 0.6 0" /> -->

        <body name="rl_l0" pos="-0.1025 0.10765 0" quat="0.707388 0 0 0.706825">
          <inertial pos="0.0557 -0.016 0" quat="0.5 0.5 0.5 0.5" mass="0.645" diaginertia="0.000847656 0.000586985 0.000492924" />

          <joint name="RL_hip_joint" class="hip" />
          <geom mesh="l0l" material="gray" class="visual" />

          <body name="rl_l1" pos="0.0555 0.0125 0" quat="9.38559e-07 0.707388 0.706825 9.37812e-07">
            <inertial pos="0.031 0.0164 -0.003" quat="0.707107 0.707107 0 0" mass="0.827" diaginertia="0.0040626 0.00387148 0.000683492" />

            <joint name="RL_thigh_joint" class="thigh" />
            <geom mesh="l1lf" material="orange" class="visual" />

            <!-- TODO: COLLISION BODIES -->
            <!-- <geom size="0.05 0.055" quat="0.707388 0 0.706825 0" type="cylinder" material="orange" /> -->

              <body name="rl_l2" pos="0.0584 0.2 0" quat="0.116034 -0.993245 0 0">
                <inertial pos="0.001 0.104 -0.003" quat="0.707107 0.707107 0 0" mass="0.118" diaginertia="0.000525296 0.000518946 2.20064e-05" />

                <joint name="RL_calf_joint" class="left_calf" />
                <geom mesh="l2l" material="gray" class="visual" />
                <!-- TODO: COLLISION BODIES -->
                <!-- <geom size="0.01 0.03125" pos="0 -0.01 0.0055" quat="0.796084 -0.605186 0 0" type="cylinder" material="gray" /> -->

                <!-- NOT SURE WHAT IT IS -->
                <!-- <geom name="RL_calf" size="0.015 0.1" pos="0 0.1 0.005" quat="0.670968 -0.741065 0.0185305 -0.0167777" type="cylinder" material="gray" /> -->

                <geom class="left_visual_foot" />
                <geom name="RL_foot" class="left_foot"/>
                <site name="RL_foot" class="left_foot" />
              </body>
          </body>
        </body>

        <body name="rr_l0" pos="0.0255 0.10725 0" quat="0.707388 0 0 0.706825">
          <inertial pos="0.0557 0.016 0" quat="0.5 0.5 0.5 0.5" mass="0.645" diaginertia="0.000847656 0.000586985 0.000492924" />

          <joint name="RR_hip_joint" class="hip" />
          <geom mesh="l0r" material="gray" class="visual" />

          <body name="rr_l1" pos="0.0555 -0.0125 0" quat="9.38559e-07 0.707388 -0.706825 -9.37812e-07">
            <inertial pos="0.031 -0.0164 -0.003" quat="0.707107 0.707107 0 0" mass="0.827" diaginertia="0.0040626 0.00387148 0.000683492" />

            <joint name="RR_thigh_joint" class="thigh" />
            <geom mesh="l1r" material="orange" class="visual" />
            <!-- TODO: COLLISION BODIES -->
            <!-- <geom size="0.05 0.055" quat="0.707388 0 0.706825 0" type="cylinder" rgba="1 0.41 0 0" /> -->

            <body name="rr_l2" pos="0.0584 -0.2 0" quat="0.116034 0.993245 0 0">
              <inertial pos="0.001 -0.104 -0.003" quat="0.707107 0.707107 0 0" mass="0.118" diaginertia="0.000525296 0.000518946 2.20064e-05" />

              <joint name="RR_calf_joint" class="right_calf" />
              <geom mesh="l2r" material="gray" class="visual" />
              <!-- TODO: COLLISION BODIES -->
              <!-- <geom size="0.01 0.03125" pos="0 0.01 0.0055" quat="0.796084 0.605186 0 0" type="cylinder" rgba="0.6 0.6 0.6 0" /> -->

              <!-- NOT SURE WHAT IT IS -->
              <!-- <geom name="RR_calf" size="0.015 0.1" pos="0 -0.1 0.005" quat="0.670968 0.741065 0.0185305 0.0167777" type="cylinder" rgba="0.6 0.6 0.6 0" /> -->

              <geom class="right_visual_foot" />
              <geom name="RR_foot" class="right_foot" />
              <site name="RR_foot" class="right_foot" />
            </body>
          </body>
        </body>
      </body>

      <body name="fr_l0" pos="0.1375 -0.064 0">
        <inertial pos="0.0557 0.016 0" quat="0.5 0.5 0.5 0.5" mass="0.645" diaginertia="0.000847656 0.000586985 0.000492924" />

        <joint name="FR_hip_joint" class="hip" />
        <geom mesh="l0r" material="gray" class="visual" />

        <body name="fr_l1" pos="0.0555 -0.0125 0" quat="0.707388 0 0 -0.706825">
          <inertial pos="0.031 -0.016 -0.003" quat="0.707107 0.707107 0 0" mass="0.827" diaginertia="0.0040626 0.00387148 0.000683492" />

          <joint name="FR_thigh_joint" class="thigh" />
          <geom mesh="l1r" material="orange" class="visual" />

          <!-- TODO: COLLISION BODIES -->
          <!-- <geom size="0.05 0.055" quat="0.707388 0 0.706825 0" type="cylinder" rgba="1 0.41 0 0" /> -->

          <body name="fr_l2" pos="0.0584 -0.2 0" quat="0.116034 0.993245 0 0">
            <inertial pos="0.001 -0.104 -0.003" quat="0.707107 0.707107 0 0" mass="0.118" diaginertia="0.000525296 0.000518946 2.20064e-05" />

            <joint name="FR_calf_joint" class="right_calf" />
            <geom mesh="l2r" material="gray" class="visual" />
            <!-- TODO: COLLISION BODIES -->
            <!-- <geom size="0.01 0.03125" pos="0 0.01 0.0055" quat="0.796084 0.605186 0 0" type="cylinder" rgba="0.6 0.6 0.6 0" /> -->

            <!-- NOT SURE WHAT IT IS -->
            <!-- <geom name="FR_calf" size="0.015 0.1" pos="0 -0.1 0.005" quat="0.670968 0.741065 0.0185305 0.0167777" type="cylinder" rgba="1 0 0 0" /> -->

            <geom class="right_visual_foot" />
            <geom name="FR_foot" class="right_foot" />
            <site name="FR_foot" class="right_foot" />
          </body>
        </body>
      </body>

      <body name="fl_l0" pos="0.1375 0.064 0">
        <inertial pos="0.0557 -0.016 0" quat="0.5 0.5 0.5 0.5" mass="0.645" diaginertia="0.000847656 0.000586985 0.000492924" />

        <joint name="FL_hip_joint" class="hip" />
        <geom mesh="l0l" material="gray" class="visual" />

        <body name="fl_l1" pos="0.0555 0.0125 0" quat="0.707388 0 0 0.706825">
          <inertial pos="0.031 0.0164 -0.003" quat="0.707107 0.707107 0 0" mass="0.827" diaginertia="0.0040626 0.00387148 0.000683492" />

          <joint name="FL_thigh_joint" class="thigh" />
          <geom mesh="l1lf" material="orange" class="visual" />

          <!-- TODO: COLLISION BODIES -->
          <!-- <geom size="0.05 0.055" quat="0.707388 0 0.706825 0" type="cylinder" rgba="1 0.41 0 0" /> -->

          <body name="fl_l2" pos="0.0584 0.2 0" quat="0.116034 -0.993245 0 0">
            <inertial pos="0.001 0.104 -0.003" quat="0.707107 0.707107 0 0" mass="0.118" diaginertia="0.000525296 0.000518946 2.20064e-05" />

            <joint name="FL_calf_joint" class="left_calf" />
            <geom mesh="l2l" material="gray" class="visual" />
            <!-- TODO: COLLISION BODIES -->
            <!-- <geom size="0.01 0.03125" pos="0 -0.01 0.0055" quat="0.796084 -0.605186 0 0" type="cylinder" rgba="0.6 0.6 0.6 0" /> -->

            <!-- NOT SURE WHAT IT IS -->
            <!-- <geom name="FL_calf" size="0.015 0.1" pos="0 0.1 0.005" quat="0.670968 -0.741065 0.0185305 -0.0167777" type="cylinder" rgba="0.6 0.6 0.6 0" /> -->

            <geom class="left_visual_foot" />
            <geom name="FL_foot" class="left_foot" />
            <site name="FL_foot" class="left_foot" />
          </body>
        </body>
      </body>
    </body>
  </worldbody>
  
  <actuator>
    <motor name="spine" class="spine" joint="spine_joint" ></motor>
    <motor name="RL_hip" class="hip" joint="RL_hip_joint" ></motor>
    <motor name="RL_thigh" class="thigh" joint="RL_thigh_joint" ></motor>
    <motor name="RL_calf" class="calf" joint="RL_calf_joint" ></motor>
    <motor name="RR_hip" class="hip" joint="RR_hip_joint" ></motor>
    <motor name="RR_thigh" class="thigh" joint="RR_thigh_joint" ></motor>
    <motor name="RR_calf" class="calf" joint="RR_calf_joint" ></motor>
    <motor name="FR_hip" class="hip" joint="FR_hip_joint" ></motor>
    <motor name="FR_thigh" class="thigh" joint="FR_thigh_joint" ></motor>
    <motor name="FR_calf" class="calf" joint="FR_calf_joint" ></motor>
    <motor name="FL_hip" class="hip" joint="FL_hip_joint" ></motor>
    <motor name="FL_thigh" class="thigh" joint="FL_thigh_joint" ></motor>
    <motor name="FL_calf" class="calf" joint="FL_calf_joint" ></motor>
    <!-- <motor name="spine" joint="spine_joint" ctrllimited="true" ctrlrange="-48 48"></motor> -->
    <!-- <motor name="RL_hip" joint="RL_hip_joint" ctrllimited="true" ctrlrange="-16 16"></motor> -->
    <!-- <motor name="RL_thigh" joint="RL_thigh_joint" ctrllimited="true" ctrlrange="-16 16"></motor> -->
    <!-- <motor name="RL_calf" joint="RL_calf_joint" ctrllimited="true" ctrlrange="-16 16"></motor> -->
    <!-- <motor name="RR_hip" joint="RR_hip_joint" ctrllimited="true" ctrlrange="-16 16"></motor> -->
    <!-- <motor name="RR_thigh" joint="RR_thigh_joint" ctrllimited="true" ctrlrange="-16 16"></motor> -->
    <!-- <motor name="RR_calf" joint="RR_calf_joint" ctrllimited="true" ctrlrange="-16 16"></motor> -->
    <!-- <motor name="FR_hip" joint="FR_hip_joint" ctrllimited="true" ctrlrange="-16 16"></motor> -->
    <!-- <motor name="FR_thigh" joint="FR_thigh_joint" ctrllimited="true" ctrlrange="-16 16"></motor> -->
    <!-- <motor name="FR_calf" joint="FR_calf_joint" ctrllimited="true" ctrlrange="-16 16"></motor> -->
    <!-- <motor name="FL_hip" joint="FL_hip_joint" ctrllimited="true" ctrlrange="-16 16"></motor> -->
    <!-- <motor name="FL_thigh" joint="FL_thigh_joint" ctrllimited="true" ctrlrange="-16 16"></motor> -->
    <!-- <motor name="FL_calf" joint="FL_calf_joint" ctrllimited="true" ctrlrange="-16 16"></motor> -->
  </actuator>

  <keyframe>
    <!-- <key name="home" qpos="0 0 0.3 1 0 0 0 0.0 0.0 -1.0 1.5 0.0 1.0 -1.5 0.0 0.8 -1.5 0.0 -0.8 1.5"/> -->
    <key name="home" qpos="0 0 0.3 1 0 0 0 0.0 -0.1 -1.0 1.5 0.1 1.0 -1.5 -0.1 0.8 -1.5 0.1 -0.8 1.5"/>
  </keyframe>
</mujoco>
